<?xml version="1.0" ?>
<!-- =================================================================================== -->
<!-- |    This document was autogenerated by xacro from roberto.xacro                  | -->
<!-- |    EDITING THIS FILE BY HAND IS NOT RECOMMENDED                                 | -->
<!-- =================================================================================== -->
<robot name="roberto" xmlns:xacro="http://www.ros.org/wiki/xacro">
  <material name="black">
    <color rgba="0.0 0.0 0.0 1.0"/>
  </material>
  <material name="blue">
    <color rgba="0.0 0.0 0.8 1.0"/>
  </material>
  <material name="green">
    <color rgba="0.0 0.8 0.0 1.0"/>
  </material>
  <material name="grey">
    <color rgba="0.3 0.3 0.3 1.0"/>
  </material>
  <material name="orange">
    <color rgba="1.0 0.423529411765 0.0392156862745 1.0"/>
  </material>
  <material name="brown">
    <color rgba="0.870588235294 0.811764705882 0.764705882353 1.0"/>
  </material>
  <material name="red">
    <color rgba="0.8 0.0 0.0 1.0"/>
  </material>
  <material name="white">
    <color rgba="1.0 1.0 1.0 1.0"/>
  </material>
  <!-- see https://secure.wikimedia.org/wikipedia/en/wiki/List_of_moment_of_inertia_tensors -->
  <!-- see https://secure.wikimedia.org/wikipedia/en/wiki/List_of_moment_of_inertia_tensors -->
  <!-- see https://secure.wikimedia.org/wikipedia/en/wiki/List_of_moment_of_inertia_tensors -->
  <!-- see https://secure.wikimedia.org/wikipedia/en/wiki/List_of_moment_of_inertia_tensors -->
  <!-- see https://secure.wikimedia.org/wikipedia/en/wiki/List_of_moment_of_inertia_tensors -->
  <!-- Base link -->
  <link name="base_link"/>
  <!--minimalist mesh-->
  <!-- joint and link definition -->
  <joint name="base2body_joint" type="fixed">
    <parent link="base_link"/>
    <child link="body_link"/>
    <!--parent link to this joint tf-->
    <origin rpy="0 0 0" xyz="0 0 0"/>
  </joint>
  <link name="body_link">
    <inertial>
      <mass value="0.2"/>
      <origin xyz="0 0 0"/>
      <inertia ixx="0.00084481632874" ixy="0.0" ixz="0.0" iyy="0.00084481632874" iyz="0.0" izz="0.001687499325"/>
    </inertial>
    <visual>
      <!--this link 2 mesh center tf, file-->
      <origin rpy="0 0 0" xyz="-0.1125 -0.1125 0.06"/>
      <geometry>
        <mesh filename="file:///windows/git/roberto/roberto_sim/src/roberto_models_jade/models/platform/roberto_body/meshes/platform.dae"/>
      </geometry>
      <!--<material name="light_blue"/> -->
    </visual>
    <collision>
      <!--this link 2 simple mesh center tf, file-->
      <origin rpy="0 0 0" xyz="0 0 0.06"/>
      <geometry>
        <box size="0.225 0.225 0.008"/>
      </geometry>
      <!--<material name="light_blue"/> -->
    </collision>
  </link>
  <gazebo reference="body_link">
    <!--<material>Gazebo/LightBlueLaser</material> -->
  </gazebo>
  <!--minimalist mesh-->
  <!-- joint and link definition -->
  <joint name="body2body_top_joint" type="fixed">
    <parent link="body_link"/>
    <child link="body_top_link"/>
    <!--parent link to this joint tf-->
    <origin rpy="0 0 0" xyz="0 0 0.095"/>
  </joint>
  <link name="body_top_link">
    <inertial>
      <mass value="0.125"/>
      <origin xyz="0 0 0"/>
      <inertia ixx="0.000266926976563" ixy="0.0" ixz="0.0" iyy="0.000337760281562" iyz="0.0" izz="0.000604166425"/>
    </inertial>
    <visual>
      <!--this link 2 mesh center tf, file-->
      <origin rpy="0 3.14159265359 0" xyz="0.09 -0.08 0"/>
      <geometry>
        <mesh filename="file:///windows/git/roberto/roberto_sim/src/roberto_models_jade/models/platform/roberto_body/meshes/platform_top.dae"/>
      </geometry>
      <!--<material name="light_blue"/> -->
    </visual>
    <collision>
      <!--this link 2 simple mesh center tf, file-->
      <origin rpy="0 3.14159265359 0" xyz="0 0 0"/>
      <geometry>
        <box size="0.18 0.16 0.005"/>
      </geometry>
      <!--<material name="light_blue"/> -->
    </collision>
  </link>
  <gazebo reference="body_top_link">
    <!--<material>Gazebo/LightBlueLaser</material> -->
  </gazebo>
  <!--minimalist mesh-->
  <!-- joint and link definition -->
  <joint name="body2spacerFL_joint" type="fixed">
    <parent link="body_link"/>
    <child link="spacerFL_link"/>
    <!--parent link to this joint tf-->
    <axis xyz="0 0 1"/>
    <origin rpy="0 0 0" xyz="-0.071 0.052 0.079"/>
  </joint>
  <link name="spacerFL_link">
    <inertial>
      <mass value="0.005"/>
      <origin xyz="0 0 0"/>
      <inertia ixx="2.21666578e-07" ixy="0.0" ixz="0.0" iyy="2.21666578e-07" iyz="0.0" izz="4e-08"/>
    </inertial>
    <visual>
      <!--this link 2 simple mesh center tf, file-->
      <origin rpy="0 0 0" xyz="0 0 0"/>
      <geometry>
        <cylinder length="0.022" radius="0.004"/>
      </geometry>
      <material name="white">
        <color rgba="1 1 1 1"/>
      </material>
    </visual>
    <collision>
      <!--this link 2 simple mesh center tf, file-->
      <origin rpy="0 0 0" xyz="0 0 0"/>
      <geometry>
        <cylinder length="0.022" radius="0.004"/>
      </geometry>
      <material name="white">
        <color rgba="1 1 1 1"/>
      </material>
    </collision>
  </link>
  <gazebo reference="spacerFL_link">
    <material>Gazebo/White</material>
    <selfCollide>false</selfCollide>
  </gazebo>
  <!--minimalist mesh-->
  <!-- joint and link definition -->
  <joint name="body2spacerFR_joint" type="fixed">
    <parent link="body_link"/>
    <child link="spacerFR_link"/>
    <!--parent link to this joint tf-->
    <axis xyz="0 0 1"/>
    <origin rpy="0 0 0" xyz="0.071 0.052 0.079"/>
  </joint>
  <link name="spacerFR_link">
    <inertial>
      <mass value="0.005"/>
      <origin xyz="0 0 0"/>
      <inertia ixx="2.21666578e-07" ixy="0.0" ixz="0.0" iyy="2.21666578e-07" iyz="0.0" izz="4e-08"/>
    </inertial>
    <visual>
      <!--this link 2 simple mesh center tf, file-->
      <origin rpy="0 0 0" xyz="0 0 0"/>
      <geometry>
        <cylinder length="0.022" radius="0.004"/>
      </geometry>
      <material name="white">
        <color rgba="1 1 1 1"/>
      </material>
    </visual>
    <collision>
      <!--this link 2 simple mesh center tf, file-->
      <origin rpy="0 0 0" xyz="0 0 0"/>
      <geometry>
        <cylinder length="0.022" radius="0.004"/>
      </geometry>
      <material name="white">
        <color rgba="1 1 1 1"/>
      </material>
    </collision>
  </link>
  <gazebo reference="spacerFR_link">
    <material>Gazebo/White</material>
    <selfCollide>false</selfCollide>
  </gazebo>
  <!--minimalist mesh-->
  <!-- joint and link definition -->
  <joint name="body2spacerBL_joint" type="fixed">
    <parent link="body_link"/>
    <child link="spacerBL_link"/>
    <!--parent link to this joint tf-->
    <axis xyz="0 0 1"/>
    <origin rpy="0 0 0" xyz="-0.071 -0.052 0.079"/>
  </joint>
  <link name="spacerBL_link">
    <inertial>
      <mass value="0.005"/>
      <origin xyz="0 0 0"/>
      <inertia ixx="2.21666578e-07" ixy="0.0" ixz="0.0" iyy="2.21666578e-07" iyz="0.0" izz="4e-08"/>
    </inertial>
    <visual>
      <!--this link 2 simple mesh center tf, file-->
      <origin rpy="0 0 0" xyz="0 0 0"/>
      <geometry>
        <cylinder length="0.022" radius="0.004"/>
      </geometry>
      <material name="white">
        <color rgba="1 1 1 1"/>
      </material>
    </visual>
    <collision>
      <!--this link 2 simple mesh center tf, file-->
      <origin rpy="0 0 0" xyz="0 0 0"/>
      <geometry>
        <cylinder length="0.022" radius="0.004"/>
      </geometry>
      <material name="white">
        <color rgba="1 1 1 1"/>
      </material>
    </collision>
  </link>
  <gazebo reference="spacerBL_link">
    <material>Gazebo/White</material>
    <selfCollide>false</selfCollide>
  </gazebo>
  <!--minimalist mesh-->
  <!-- joint and link definition -->
  <joint name="body2spacerBR_joint" type="fixed">
    <parent link="body_link"/>
    <child link="spacerBR_link"/>
    <!--parent link to this joint tf-->
    <axis xyz="0 0 1"/>
    <origin rpy="0 0 0" xyz="0.071 -0.052 0.079"/>
  </joint>
  <link name="spacerBR_link">
    <inertial>
      <mass value="0.005"/>
      <origin xyz="0 0 0"/>
      <inertia ixx="2.21666578e-07" ixy="0.0" ixz="0.0" iyy="2.21666578e-07" iyz="0.0" izz="4e-08"/>
    </inertial>
    <visual>
      <!--this link 2 simple mesh center tf, file-->
      <origin rpy="0 0 0" xyz="0 0 0"/>
      <geometry>
        <cylinder length="0.022" radius="0.004"/>
      </geometry>
      <material name="white">
        <color rgba="1 1 1 1"/>
      </material>
    </visual>
    <collision>
      <!--this link 2 simple mesh center tf, file-->
      <origin rpy="0 0 0" xyz="0 0 0"/>
      <geometry>
        <cylinder length="0.022" radius="0.004"/>
      </geometry>
      <material name="white">
        <color rgba="1 1 1 1"/>
      </material>
    </collision>
  </link>
  <gazebo reference="spacerBR_link">
    <material>Gazebo/White</material>
    <selfCollide>false</selfCollide>
  </gazebo>
  <!--minimalist mesh-->
  <!-- joint and link definition -->
  <joint name="body2mountBR_joint" type="revolute">
    <parent link="body_link"/>
    <child link="mountBR_link"/>
    <!--parent link to this joint tf-->
    <origin rpy="0 0 0" xyz="0.085 -0.085 0.04"/>
    <axis rpy="0 0 0" xyz="0 0 1"/>
    <limit effort="10.0" lower="-1.57" upper="0.2618" velocity="4"/>
    <!--<dynamics damping="0.7" />-->
    <!--<origin xyz="${wheelPos*tY} 0 0" rpy="0 0 0" />
      <limit effort="10" velocity="4"/>-->
  </joint>
  <link name="mountBR_link">
    <inertial>
      <mass value="0.19"/>
      <origin rpy="0 1.57079632679 0" xyz="0 0 0"/>
      <inertia ixx="0.0001203332852" ixy="0.0" ixz="0.0" iyy="0.0001203332852" iyz="0.0" izz="3.8e-05"/>
    </inertial>
    <visual>
      <!--this link 2 simple mesh center tf, file-->
      <origin rpy="0 1.57079632679 0" xyz="0 0 0"/>
      <geometry>
        <cylinder length="0.08" radius="0.02"/>
      </geometry>
      <material name="grey"/>
    </visual>
    <collision>
      <!--this link 2 simple mesh center tf, file-->
      <origin rpy="0 1.57079632679 0" xyz="0 0 0"/>
      <geometry>
        <cylinder length="0.08" radius="0.02"/>
      </geometry>
      <material name="grey"/>
    </collision>
  </link>
  <gazebo reference="mountBR_link">
    <mu1>5.9</mu1>
    <mu2>5.9</mu2>
    <kp>1000000.0</kp>
    <kd>100.0</kd>
    <minDepth>0.001</minDepth>
    <maxVel>1.0</maxVel>
    <material>Gazebo/Grey</material>
  </gazebo>
  <!--minimalist mesh-->
  <!-- joint and link definition -->
  <joint name="body2mountBL_joint" type="revolute">
    <parent link="body_link"/>
    <child link="mountBL_link"/>
    <!--parent link to this joint tf-->
    <origin rpy="0 0 0" xyz="-0.085 -0.085 0.04"/>
    <axis rpy="0 0 0" xyz="0 0 1"/>
    <limit effort="10.0" lower="-0.2618" upper="1.57" velocity="4"/>
    <!--<dynamics damping="0.7" />-->
    <!--<origin xyz="${wheelPos*tY} 0 0" rpy="0 0 0" />
      <limit effort="10" velocity="4"/>-->
  </joint>
  <link name="mountBL_link">
    <inertial>
      <mass value="0.19"/>
      <origin rpy="0 1.57079632679 0" xyz="0 0 0"/>
      <inertia ixx="0.0001203332852" ixy="0.0" ixz="0.0" iyy="0.0001203332852" iyz="0.0" izz="3.8e-05"/>
    </inertial>
    <visual>
      <!--this link 2 simple mesh center tf, file-->
      <origin rpy="0 1.57079632679 0" xyz="0 0 0"/>
      <geometry>
        <cylinder length="0.08" radius="0.02"/>
      </geometry>
      <material name="grey"/>
    </visual>
    <collision>
      <!--this link 2 simple mesh center tf, file-->
      <origin rpy="0 1.57079632679 0" xyz="0 0 0"/>
      <geometry>
        <cylinder length="0.08" radius="0.02"/>
      </geometry>
      <material name="grey"/>
    </collision>
  </link>
  <gazebo reference="mountBL_link">
    <mu1>5.9</mu1>
    <mu2>5.9</mu2>
    <kp>1000000.0</kp>
    <kd>100.0</kd>
    <minDepth>0.001</minDepth>
    <maxVel>1.0</maxVel>
    <material>Gazebo/Grey</material>
  </gazebo>
  <!--minimalist mesh-->
  <!-- joint and link definition -->
  <joint name="body2mountFL_joint" type="revolute">
    <parent link="body_link"/>
    <child link="mountFL_link"/>
    <!--parent link to this joint tf-->
    <origin rpy="0 0 0" xyz="-0.085 0.085 0.04"/>
    <axis rpy="0 0 0" xyz="0 0 1"/>
    <limit effort="10.0" lower="-1.57" upper="0.2618" velocity="4"/>
    <!--<dynamics damping="0.7" />-->
    <!--<origin xyz="${wheelPos*tY} 0 0" rpy="0 0 0" />
      <limit effort="10" velocity="4"/>-->
  </joint>
  <link name="mountFL_link">
    <inertial>
      <mass value="0.19"/>
      <origin rpy="0 1.57079632679 0" xyz="0 0 0"/>
      <inertia ixx="9.65832947e-05" ixy="0.0" ixz="0.0" iyy="9.65832947e-05" iyz="0.0" izz="3.8e-05"/>
    </inertial>
    <visual>
      <!--this link 2 simple mesh center tf, file-->
      <origin rpy="0 1.57079632679 0" xyz="0 0 0"/>
      <geometry>
        <cylinder length="0.07" radius="0.02"/>
      </geometry>
      <material name="grey"/>
    </visual>
    <collision>
      <!--this link 2 simple mesh center tf, file-->
      <origin rpy="0 1.57079632679 0" xyz="0 0 0"/>
      <geometry>
        <cylinder length="0.07" radius="0.02"/>
      </geometry>
      <material name="grey"/>
    </collision>
  </link>
  <gazebo reference="mountFL_link">
    <mu1>5.9</mu1>
    <mu2>5.9</mu2>
    <kp>1000000.0</kp>
    <kd>100.0</kd>
    <minDepth>0.001</minDepth>
    <maxVel>1.0</maxVel>
    <material>Gazebo/Grey</material>
  </gazebo>
  <!--minimalist mesh-->
  <!-- joint and link definition -->
  <joint name="body2mountFR_joint" type="revolute">
    <parent link="body_link"/>
    <child link="mountFR_link"/>
    <!--parent link to this joint tf-->
    <origin rpy="0 0 0" xyz="0.085 0.085 0.04"/>
    <axis rpy="0 0 0" xyz="0 0 1"/>
    <limit effort="10.0" lower="-0.2618" upper="1.57" velocity="4"/>
    <!--<dynamics damping="0.7" />-->
    <!--<origin xyz="${wheelPos*tY} 0 0" rpy="0 0 0" />
      <limit effort="10" velocity="4"/>-->
  </joint>
  <link name="mountFR_link">
    <inertial>
      <mass value="0.19"/>
      <origin rpy="0 1.57079632679 0" xyz="0 0 0"/>
      <inertia ixx="9.65832947e-05" ixy="0.0" ixz="0.0" iyy="9.65832947e-05" iyz="0.0" izz="3.8e-05"/>
    </inertial>
    <visual>
      <!--this link 2 simple mesh center tf, file-->
      <origin rpy="0 1.57079632679 0" xyz="0 0 0"/>
      <geometry>
        <cylinder length="0.07" radius="0.02"/>
      </geometry>
      <material name="grey"/>
    </visual>
    <collision>
      <!--this link 2 simple mesh center tf, file-->
      <origin rpy="0 1.57079632679 0" xyz="0 0 0"/>
      <geometry>
        <cylinder length="0.07" radius="0.02"/>
      </geometry>
      <material name="grey"/>
    </collision>
  </link>
  <gazebo reference="mountFR_link">
    <mu1>5.9</mu1>
    <mu2>5.9</mu2>
    <kp>1000000.0</kp>
    <kd>100.0</kd>
    <minDepth>0.001</minDepth>
    <maxVel>1.0</maxVel>
    <material>Gazebo/Grey</material>
  </gazebo>
  <!--minimalist mesh-->
  <!-- joint and link definition -->
  <joint name="mountFL2wheelFL_joint" type="continuous">
    <parent link="mountFL_link"/>
    <child link="wheelFL_link"/>
    <!--parent link to this joint tf-->
    <origin rpy="0 0 0" xyz="-0.05 0 0"/>
    <axis rpy="0 0 0" xyz="1 0 0"/>
    <!--<dynamics damping="0.7" />-->
    <!--<limit effort="10" velocity="4"/>
      <joint_properties damping="0.0" friction="0.0"/>-->
  </joint>
  <link name="wheelFL_link">
    <inertial>
      <mass value="0.045"/>
      <origin rpy="0 1.57079632679 0" xyz="0 0 0"/>
      <inertia ixx="2.137499145e-05" ixy="0.0" ixz="0.0" iyy="2.137499145e-05" iyz="0.0" izz="3.6e-05"/>
    </inertial>
    <visual>
      <!--this link 2 simple mesh center tf, file-->
      <origin rpy="0 1.57079632679 0" xyz="0 0 0"/>
      <geometry>
        <cylinder length="0.03" radius="0.04"/>
      </geometry>
      <material name="black"/>
    </visual>
    <collision>
      <!--this link 2 simple mesh center tf, file-->
      <origin rpy="0 1.57079632679 0" xyz="0 0 0"/>
      <geometry>
        <cylinder length="0.03" radius="0.04"/>
      </geometry>
      <material name="black"/>
    </collision>
  </link>
  <gazebo reference="wheelFL_link">
    <!--<selfCollide>false</selfCollide>-->
    <mu1>5.9</mu1>
    <kp>1000000.0</kp>
    <kd>100.0</kd>
    <minDepth>0.001</minDepth>
    <maxVel>1.0</maxVel>
    <material>Gazebo/Black</material>
  </gazebo>
  <!--minimalist mesh-->
  <!-- joint and link definition -->
  <joint name="mountFR2wheelFR_joint" type="continuous">
    <parent link="mountFR_link"/>
    <child link="wheelFR_link"/>
    <!--parent link to this joint tf-->
    <origin rpy="0 0 0" xyz="0.05 0 0"/>
    <axis rpy="0 0 0" xyz="1 0 0"/>
    <!--<dynamics damping="0.7" />-->
    <!--<limit effort="10" velocity="4"/>
      <joint_properties damping="0.0" friction="0.0"/>-->
  </joint>
  <link name="wheelFR_link">
    <inertial>
      <mass value="0.045"/>
      <origin rpy="0 1.57079632679 0" xyz="0 0 0"/>
      <inertia ixx="2.137499145e-05" ixy="0.0" ixz="0.0" iyy="2.137499145e-05" iyz="0.0" izz="3.6e-05"/>
    </inertial>
    <visual>
      <!--this link 2 simple mesh center tf, file-->
      <origin rpy="0 1.57079632679 0" xyz="0 0 0"/>
      <geometry>
        <cylinder length="0.03" radius="0.04"/>
      </geometry>
      <material name="black"/>
    </visual>
    <collision>
      <!--this link 2 simple mesh center tf, file-->
      <origin rpy="0 1.57079632679 0" xyz="0 0 0"/>
      <geometry>
        <cylinder length="0.03" radius="0.04"/>
      </geometry>
      <material name="black"/>
    </collision>
  </link>
  <gazebo reference="wheelFR_link">
    <!--<selfCollide>false</selfCollide>-->
    <mu1>5.9</mu1>
    <kp>1000000.0</kp>
    <kd>100.0</kd>
    <minDepth>0.001</minDepth>
    <maxVel>1.0</maxVel>
    <material>Gazebo/Black</material>
  </gazebo>
  <!--minimalist mesh-->
  <!-- joint and link definition -->
  <joint name="mountBL2wheelBL_joint" type="continuous">
    <parent link="mountBL_link"/>
    <child link="wheelBL_link"/>
    <!--parent link to this joint tf-->
    <origin rpy="0 0 0" xyz="-0.05 0 0"/>
    <axis rpy="0 0 0" xyz="1 0 0"/>
    <!--<dynamics damping="0.7" />-->
    <!--<limit effort="10" velocity="4"/>
      <joint_properties damping="0.0" friction="0.0"/>-->
  </joint>
  <link name="wheelBL_link">
    <inertial>
      <mass value="0.05"/>
      <origin rpy="0 1.57079632679 0" xyz="0 0 0"/>
      <inertia ixx="2.6666656e-05" ixy="0.0" ixz="0.0" iyy="2.6666656e-05" iyz="0.0" izz="4e-05"/>
    </inertial>
    <visual>
      <!--this link 2 simple mesh center tf, file-->
      <origin rpy="0 1.57079632679 0" xyz="0 0 0"/>
      <geometry>
        <cylinder length="0.04" radius="0.04"/>
      </geometry>
      <material name="black"/>
    </visual>
    <collision>
      <!--this link 2 simple mesh center tf, file-->
      <origin rpy="0 1.57079632679 0" xyz="0 0 0"/>
      <geometry>
        <cylinder length="0.04" radius="0.04"/>
      </geometry>
      <material name="black"/>
    </collision>
  </link>
  <gazebo reference="wheelBL_link">
    <!--<selfCollide>false</selfCollide>-->
    <mu1>5.9</mu1>
    <kp>1000000.0</kp>
    <kd>100.0</kd>
    <minDepth>0.001</minDepth>
    <maxVel>1.0</maxVel>
    <material>Gazebo/Black</material>
  </gazebo>
  <!--minimalist mesh-->
  <!-- joint and link definition -->
  <joint name="mountBR2wheelBR_joint" type="continuous">
    <parent link="mountBR_link"/>
    <child link="wheelBR_link"/>
    <!--parent link to this joint tf-->
    <origin rpy="0 0 0" xyz="0.05 0 0"/>
    <axis rpy="0 0 0" xyz="1 0 0"/>
    <!--<dynamics damping="0.7" />-->
    <!--<limit effort="10" velocity="4"/>
      <joint_properties damping="0.0" friction="0.0"/>-->
  </joint>
  <link name="wheelBR_link">
    <inertial>
      <mass value="0.05"/>
      <origin rpy="0 1.57079632679 0" xyz="0 0 0"/>
      <inertia ixx="2.6666656e-05" ixy="0.0" ixz="0.0" iyy="2.6666656e-05" iyz="0.0" izz="4e-05"/>
    </inertial>
    <visual>
      <!--this link 2 simple mesh center tf, file-->
      <origin rpy="0 1.57079632679 0" xyz="0 0 0"/>
      <geometry>
        <cylinder length="0.04" radius="0.04"/>
      </geometry>
      <material name="black"/>
    </visual>
    <collision>
      <!--this link 2 simple mesh center tf, file-->
      <origin rpy="0 1.57079632679 0" xyz="0 0 0"/>
      <geometry>
        <cylinder length="0.04" radius="0.04"/>
      </geometry>
      <material name="black"/>
    </collision>
  </link>
  <gazebo reference="wheelBR_link">
    <!--<selfCollide>false</selfCollide>-->
    <mu1>5.9</mu1>
    <kp>1000000.0</kp>
    <kd>100.0</kd>
    <minDepth>0.001</minDepth>
    <maxVel>1.0</maxVel>
    <material>Gazebo/Black</material>
  </gazebo>
  <!-- simplified detailed empty-->
  <gazebo>
    <plugin filename="libroberto_gazebo_ros_control.so" name="roberto_motor_drive">
      <robotNamespace/>
      <rosDebugLevel>Debug</rosDebugLevel>
      <alwaysOn>1</alwaysOn>
      <updateRate>50.0</updateRate>
      <robotBaseFrame>base_link</robotBaseFrame>
      <odometryFrame>odom</odometryFrame>
      <commandTopic>cmd_vel</commandTopic>
      <odometryTopic>odom</odometryTopic>
      <odometrySource>encoder</odometrySource>
      <servoLeftJoint>body2mountFL_joint</servoLeftJoint>
      <servoRightJoint>body2mountFR_joint</servoRightJoint>
      <servoLeftMimicJoint>body2mountBL_joint</servoLeftMimicJoint>
      <servoRightMimicJoint>body2mountBR_joint</servoRightMimicJoint>
      <frontLeftJoint>mountFL2wheelFL_joint</frontLeftJoint>
      <frontRightJoint>mountFR2wheelFR_joint</frontRightJoint>
      <rearLeftJoint>mountBL2wheelBL_joint</rearLeftJoint>
      <rearRightJoint>mountBR2wheelBR_joint</rearRightJoint>
      <wheelDiameter>0.08</wheelDiameter>
      <wheelTorque>10</wheelTorque>
      <wheelAcceleration>1.5</wheelAcceleration>
      <!--<wheelAcceleration>0</wheelAcceleration>-->
      <widthBetweenMotorPivotPoints>0.17</widthBetweenMotorPivotPoints>
      <motorPivotPointToWheel>0.045</motorPivotPointToWheel>
      <publishTf>1</publishTf>
      <publishWheelTF>true</publishWheelTF>
      <publishWheelJointState>true</publishWheelJointState>
    </plugin>
  </gazebo>
  <!-- IMU 
    <xacro:property name="model_dir" value="$(find roberto_models_jade)/models/sensors/imu"/>
    <xacro:include filename="$(find roberto_models_jade)/models/sensors/imu/imu.xacro"/>
    <xacro:imu_sensor name="imu9dof" parent="base_link" xyz="0.0 0.05 0.262" rpy="0 0 ${pi/2}"/>-->
  <joint name="body_top_front_camera_base_joint" type="fixed">
    <origin rpy="0 0 1.57079632679" xyz="0 0.01 0.0375"/>
    <parent link="body_top_link"/>
    <child link="front_camera_base"/>
  </joint>
  <joint name="front_camera_base_front_camera_spacer1_joint" type="fixed">
    <origin rpy="0 0 0" xyz="0.02 0.038 -0.0175"/>
    <parent link="front_camera_base"/>
    <child link="front_camera_spacer1"/>
  </joint>
  <joint name="front_camera_base_front_camera_spacer2_joint" type="fixed">
    <origin rpy="0 0 0" xyz="-0.02 0.038 -0.0175"/>
    <parent link="front_camera_base"/>
    <child link="front_camera_spacer2"/>
  </joint>
  <joint name="front_camera_base_front_camera_spacer3_joint" type="fixed">
    <origin rpy="0 0 0" xyz="0.02 -0.038 -0.0175"/>
    <parent link="front_camera_base"/>
    <child link="front_camera_spacer3"/>
  </joint>
  <joint name="front_camera_base_front_camera_spacer4_joint" type="fixed">
    <origin rpy="0 0 0" xyz="-0.02 -0.038 -0.0175"/>
    <parent link="front_camera_base"/>
    <child link="front_camera_spacer4"/>
  </joint>
  <joint name="front_camera_base_front_camera_side_left_joint" type="fixed">
    <origin rpy="1.57079632679 1.57079632679 0" xyz="0 0.0275 0.0275"/>
    <parent link="front_camera_base"/>
    <child link="front_camera_side_left"/>
  </joint>
  <joint name="front_camera_base_front_camera_side_right_joint" type="fixed">
    <origin rpy="1.57079632679 1.57079632679 0" xyz="0 -0.0275 0.0275"/>
    <parent link="front_camera_base"/>
    <child link="front_camera_side_right"/>
  </joint>
  <joint name="front_camera_side_right_front_camera_mount_joint" type="fixed">
    <origin rpy="1.88495559215 1.57079632679 0" xyz="-0.02125 0 -0.027"/>
    <parent link="front_camera_side_right"/>
    <child link="front_camera_mount"/>
  </joint>
  <joint name="front_camera_mount_front_camera_cam_joint" type="fixed">
    <origin rpy="0 3.14159265359 0" xyz="0 0 -0.0215"/>
    <parent link="front_camera_mount"/>
    <child link="front_camera"/>
  </joint>
  <link name="front_camera_base">
    <inertial>
      <mass value="0.015"/>
      <origin xyz="0 0 0"/>
      <inertia ixx="9.062496375e-06" ixy="0.0" ixz="0.0" iyy="3.1562487375e-06" iyz="0.0" izz="1.21562451375e-05"/>
    </inertial>
    <visual>
      <origin rpy="0 0 0" xyz="0 0 0"/>
      <geometry>
        <box size="0.05 0.085 0.005"/>
      </geometry>
      <material name="grey"/>
    </visual>
    <collision>
      <origin rpy="0 0 0" xyz="0 0 0"/>
      <geometry>
        <box size="0.05 0.085 0.005"/>
      </geometry>
    </collision>
  </link>
  <link name="front_camera_spacer1">
    <inertial>
      <mass value="0.005"/>
      <origin xyz="0 0 0"/>
      <inertia ixx="5.154164605e-07" ixy="0.0" ixz="0.0" iyy="5.154164605e-07" iyz="0.0" izz="1e-08"/>
    </inertial>
    <visual>
      <origin rpy="0 0 0" xyz="0 0 0"/>
      <geometry>
        <cylinder length="0.035" radius="0.002"/>
      </geometry>
      <material name="grey"/>
    </visual>
    <collision>
      <origin rpy="0 0 0" xyz="0 0 0"/>
      <geometry>
        <cylinder length="0.035" radius="0.002"/>
      </geometry>
    </collision>
  </link>
  <link name="front_camera_spacer2">
    <inertial>
      <mass value="0.005"/>
      <origin xyz="0 0 0"/>
      <inertia ixx="5.154164605e-07" ixy="0.0" ixz="0.0" iyy="5.154164605e-07" iyz="0.0" izz="1e-08"/>
    </inertial>
    <visual>
      <origin rpy="0 0 0" xyz="0 0 0"/>
      <geometry>
        <cylinder length="0.035" radius="0.002"/>
      </geometry>
      <material name="grey"/>
    </visual>
    <collision>
      <origin rpy="0 0 0" xyz="0 0 0"/>
      <geometry>
        <cylinder length="0.035" radius="0.002"/>
      </geometry>
    </collision>
  </link>
  <link name="front_camera_spacer3">
    <inertial>
      <mass value="0.005"/>
      <origin xyz="0 0 0"/>
      <inertia ixx="5.154164605e-07" ixy="0.0" ixz="0.0" iyy="5.154164605e-07" iyz="0.0" izz="1e-08"/>
    </inertial>
    <visual>
      <origin rpy="0 0 0" xyz="0 0 0"/>
      <geometry>
        <cylinder length="0.035" radius="0.002"/>
      </geometry>
      <material name="grey"/>
    </visual>
    <collision>
      <origin rpy="0 0 0" xyz="0 0 0"/>
      <geometry>
        <cylinder length="0.035" radius="0.002"/>
      </geometry>
    </collision>
  </link>
  <link name="front_camera_spacer4">
    <inertial>
      <mass value="0.005"/>
      <origin xyz="0 0 0"/>
      <inertia ixx="5.154164605e-07" ixy="0.0" ixz="0.0" iyy="5.154164605e-07" iyz="0.0" izz="1e-08"/>
    </inertial>
    <visual>
      <origin rpy="0 0 0" xyz="0 0 0"/>
      <geometry>
        <cylinder length="0.035" radius="0.002"/>
      </geometry>
      <material name="grey"/>
    </visual>
    <collision>
      <origin rpy="0 0 0" xyz="0 0 0"/>
      <geometry>
        <cylinder length="0.035" radius="0.002"/>
      </geometry>
    </collision>
  </link>
  <link name="front_camera_side_left">
    <inertial>
      <mass value="0.01"/>
      <origin xyz="0 0 0"/>
      <inertia ixx="7.57499697e-07" ixy="0.0" ixz="0.0" iyy="2.090832497e-06" iyz="0.0" izz="2.8333322e-06"/>
    </inertial>
    <visual>
      <origin rpy="0 0 0" xyz="0 0 0"/>
      <geometry>
        <box size="0.05 0.03 0.003"/>
      </geometry>
      <material name="grey"/>
    </visual>
    <collision>
      <origin rpy="0 0 0" xyz="0 0 0"/>
      <geometry>
        <box size="0.05 0.03 0.003"/>
      </geometry>
    </collision>
  </link>
  <link name="front_camera_side_right">
    <inertial>
      <mass value="0.01"/>
      <origin xyz="0 0 0"/>
      <inertia ixx="7.57499697e-07" ixy="0.0" ixz="0.0" iyy="2.090832497e-06" iyz="0.0" izz="2.8333322e-06"/>
    </inertial>
    <visual>
      <origin rpy="0 0 0" xyz="0 0 0"/>
      <geometry>
        <box size="0.05 0.03 0.003"/>
      </geometry>
      <material name="grey"/>
    </visual>
    <collision>
      <origin rpy="0 0 0" xyz="0 0 0"/>
      <geometry>
        <box size="0.05 0.03 0.003"/>
      </geometry>
    </collision>
  </link>
  <link name="front_camera_mount">
    <inertial>
      <mass value="0.01"/>
      <origin xyz="0 0 0"/>
      <inertia ixx="5.28333122e-07" ixy="0.0" ixz="0.0" iyy="2.090832497e-06" iyz="0.0" izz="2.604165625e-06"/>
    </inertial>
    <visual>
      <origin rpy="0 0 0" xyz="0 0 -0.015"/>
      <geometry>
        <box size="0.05 0.025 0.003"/>
      </geometry>
      <material name="grey"/>
    </visual>
    <collision>
      <origin rpy="0 0 0" xyz="0 0 -0.015"/>
      <geometry>
        <box size="0.05 0.025 0.003"/>
      </geometry>
    </collision>
  </link>
  <!-- Camera -->
  <link name="front_camera">
    <inertial>
      <mass value="0.1"/>
      <origin xyz="0 0 0"/>
      <inertia ixx="1.1395828775e-06" ixy="0.0" ixz="0.0" iyy="1.1395828775e-06" iyz="0.0" izz="6.125e-07"/>
    </inertial>
    <visual>
      <origin rpy="0 0 0" xyz="0 0 0"/>
      <geometry>
        <cylinder length="0.01" radius="0.0035"/>
      </geometry>
      <material name="grey"/>
    </visual>
    <collision>
      <origin rpy="0 0 0" xyz="0 0 0"/>
      <geometry>
        <cylinder length="0.01" radius="0.0035"/>
      </geometry>
    </collision>
  </link>
  <gazebo reference="front_camera">
    <material value="Gazebo/Grey"/>
  </gazebo>
  <gazebo reference="front_camera">
    <sensor name="camera1" type="camera">
      <update_rate>30.0</update_rate>
      <camera name="head">
        <pose>0 0 0 0 -1.57079632679  1.57079632679</pose>
        <horizontal_fov>1.18682389133</horizontal_fov>
        <image>
          <width>1280</width>
          <height>720</height>
          <format>R8G8B8</format>
        </image>
        <clip>
          <near>0.02</near>
          <far>300</far>
        </clip>
        <noise>
          <type>gaussian</type>
          <!-- Noise is sampled independently per pixel on each frame.  
               That pixel's noise value is added to each of its color
               channels, which at that point lie in the range [0,1]. -->
          <mean>0.0</mean>
          <stddev>0.007</stddev>
        </noise>
      </camera>
      <plugin filename="libgazebo_ros_camera.so" name="camera_controller">
        <robotNamespace/>
        <alwaysOn>true</alwaysOn>
        <updateRate>0.0</updateRate>
        <cameraName>front_camera</cameraName>
        <imageTopicName>image_raw</imageTopicName>
        <cameraInfoTopicName>camera_info</cameraInfoTopicName>
        <frameName>front_camera</frameName>
        <hackBaseline>0.00</hackBaseline>
        <distortionK1>0.0</distortionK1>
        <distortionK2>0.0</distortionK2>
        <distortionK3>0.0</distortionK3>
        <distortionT1>0.0</distortionT1>
        <distortionT2>0.0</distortionT2>
      </plugin>
    </sensor>
  </gazebo>
</robot>

